Workbook

Sheet 0 README
A1: OEM Assessment Pack — Ammonia-Fuelled 4-Stroke Gas Engine
A2: MYSGH2 project · Singapore offtake / power-generation side · prepared for OEM technology meetings. Companion to power_generation/NH3_gas_turbine_vs_gas_engine_comprehensive_comparison.md and ../memory.md.
A5: PURPOSE
B6: A structured pack for face-to-face technical and commercial meetings with reciprocating-engine OEMs offering ammonia-fuelled 4-stroke engines. It is built to answer one question: is this technology de-risked enough to buy, and on what contractual terms.
B7: Assessment focus, per the brief: (1) efficiency, (2) technical maturity — combustor, fuel supply, emission control, (3) fuel-transition behaviour and loss of firing, (4) performance / contractual de-risking, (5) long-lead items and the purchase-to-commissioning timeline, (6) preferred EPC and execution model.
A9: SHEET INDEX
A10: 0 README | B10: This sheet — purpose, how to use, legend, worked example.
A11: 1 Questionnaire | B11: 149 questions in 14 sections (A-N). Issue to the OEM in advance, then work through it in the meeting. Columns H-J are for capture during/after the meeting.
A12: 2 Assessment Criteria | B12: 10 weighted criteria with a 1-5 rubric (anchors defined at 1, 3 and 5) plus knock-out gates. Weights are a proposed starting point — edit them.
A13: 3 Scorecard | B13: Live scoring for up to three OEMs. Weights and criterion names are pulled by formula from sheet 2; you enter only the raw 1-5 scores and the knock-out verdicts.
A14: 4 Long Lead and Schedule | B14: Long-lead item register plus the purchase-order-to-commercial-operation milestone template (populate from questions K-01 to K-10).
A15: 5 Contract De-risking | B15: Contract and guarantee checklist: our target position vs. the OEM's position, gap and de-risk action (populate from section M).
A16: 6 Reference Notes | B16: Sourced technical anchors carried over from ../memory.md, so you can challenge an OEM answer in the room. Every line is tagged Sourced / Derived / Assumption / Not published.
A18: HOW TO USE
A19: Step 1 | B19: Send sheet 1 to the OEM at least two weeks before the meeting, with the 'Evidence to request' column visible. Ask for written answers to every question marked Critical.
A20: Step 2 | B20: In the meeting, capture answers in column H, the evidence actually received in column I, and any gap or follow-up in column J. Set column K to Answered / Partial / Refused / Not asked.
A21: Step 3 | B21: Review sheet 2 and adjust the weights to reflect this project's priorities before anyone scores anything. Record who set the weights and when (cells at the bottom of sheet 2).
A22: Step 4 | B22: Apply the knock-out gates on sheet 3 FIRST. A failed knock-out is not a low score — it removes the OEM from the comparison.
A23: Step 5 | B23: Score each surviving OEM 1-5 against the rubric on sheet 2, one criterion at a time, using the question responses as evidence. The weighted total on sheet 3 lands on the same 1-5 scale.
A24: Step 6 | B24: Run the sensitivity check on sheet 3: move the largest weight by 10 percentage points and see whether the ranking flips. If it does, the decision is fragile — say so in the recommendation.
A26: LEGEND — WHICH CELLS TO EDIT
A27: Yellow fill | B27: Input cell — you or the OEM fills this in. These are the only cells you should type into.
A28: White / grey fill | B28: Fixed content — question text, rubric anchors, headers. Do not overwrite.
A29: Green fill | B29: Formula cell — calculated automatically (weighted scores, totals, cumulative schedule weeks). Do not overwrite.
A30: Blue text | B30: A value carried in from another sheet by formula.
A32: NO-FABRICATION RULE (repo CLAUDE.md section 7)
B33: This workbook deliberately contains NO invented OEM performance figures, lead times, prices or efficiencies. Every quantitative cell that would hold OEM data is left blank for the OEM to fill. The only numbers pre-entered anywhere are (a) the proposed criterion weights on sheet 2, which are a judgement call and labelled as such, and (b) the published reference anchors on sheet 6, each carrying its source and a Sourced / Derived / Assumption tag.
A35: WORKED EXAMPLE — expected format (illustrative only, NOT OEM data)
A36: Questionnaire row (sheet 1)
A37: ID | B37: OEM response (col H) | C37: Evidence received (col I) | D37: Gap / follow-up (col J) | E37: Status (col K)
A38: C-09 | B38: Per-cylinder pressure sensing; misfire detected within 3 cycles; single-cyl misfire = auto pilot-fuel reversion on that cylinder, no trip. [ILLUSTRATIVE FORMAT ONLY] | C38: Trip matrix rev B received; testbed traces NOT provided | D38: Chase testbed traces + observed misfire rate; re-ask C-06 | E38: Partial
A40: Scorecard row (sheet 3)
A41: Criterion | B41: Weight | C41: Raw score 1-5 | D41: Weighted | E41: Note
A42: C1 Ammonia combustion system maturity | B42: 16% | C42: 3 | D42: 0.48 | E42: Multi-cylinder testbed hours only; no field unit. [ILLUSTRATIVE FORMAT ONLY]
A44: Prepared: | B44: 2026-08-19 · MYSGH2 project · revision 1
A45: Delete the two grey example blocks above before issuing the pack.

Sheet 1 Questionnaire
A1: Sheet 1 — OEM Questionnaire: Ammonia 4-Stroke Gas Engine
A2: Sections A-N. Columns A-G are the question set (issue to the OEM in advance). Columns H-K (yellow) are capture columns — fill during and after the meeting. 'Criterion' links each question to the weighted criterion it feeds on sheet 2.
C3: Questions: | D3: =COUNTIF(A5:A180,"?-??") | E3: Critical: | F3: =COUNTIF(E5:E180,"Critical") | H3: Answered: | I3: =COUNTIF(K5:K180,"Answered") | J3: Unanswered Critical: | K3: =COUNTIFS(E5:E180,"Critical",K5:K180,"<>Answered")
A4: ID | B4: Question | C4: Why it matters / what a good answer looks like | D4: Evidence to request | E4: Priority | F4: Feeds criterion | H4: OEM response | I4: Evidence received | J4: Gap / follow-up action | K4: Status
A5: A — Company, product identity & reference fleet
A6: A-01 | B6: Confirm the legal entity that will contract and guarantee performance, the manufacturing site(s) for the ammonia variant, and whether a parent company stands behind the guarantee. | C6: Ammonia engines are often sold by a group entity while the guarantee sits elsewhere. Good = one named entity with a parent company guarantee. | D6: Corporate structure chart; draft PCG wording | E6: Critical | F6: C7
A7: A-02 | B7: State the exact engine type designation offered for ammonia 4-stroke operation: bore x stroke, rated speed (rpm), cylinder configuration and number of cylinders offered, MW per unit. | C7: Fixes the technical baseline. Good = a designated ammonia model, not 'the NG engine, ammonia-ready'. | D7: Technical data sheet for the ammonia variant | E7: Critical | F7: C2
A8: A-03 | B8: Is the ammonia variant a new-build platform or a derivative/conversion of an existing NG or diesel platform? Name the parent platform and its accumulated field hours and installed base. | C8: Inherited platform maturity is real risk reduction — but only for the non-combustion parts. | D8: Parent platform installed base and fleet hours | E8: Critical | F8: C2
A9: A-04 | B9: List every ammonia-fuelled engine built to date: unit/site, MW, cylinder count, commissioning date, cumulative hours on ammonia, maximum ammonia energy share achieved in service, duty (marine propulsion / marine auxiliary / stationary power). | C9: This is the single most decision-relevant maturity datum. Good = multi-thousand hours on multi-cylinder hardware at the offered ammonia share. | D9: Fleet list with hours; customer references | E9: Critical | F9: C2
A10: A-05 | B10: Split accumulated ammonia hours across (a) single-cylinder research engine, (b) full multi-cylinder engine on the testbed, (c) in-field operation. | C10: Single-cylinder hours do not de-risk cylinder-to-cylinder balancing, turbocharger matching or transient behaviour. | D10: Test programme summary with hour counts | E10: Critical | F10: C2
A11: A-06 | B11: Which of those units are stationary power generation rather than marine? What specifically must change to convert the marine product into a stationary genset (rating, speed, generator, controls, emissions kit, approvals)? | C11: Ammonia 4-stroke development is marine-led. The marine-to-stationary delta is where FOAK risk hides. | D11: Marine-to-stationary scope delta statement | E11: Critical | F11: C2
A12: A-07 | B12: What is the earliest date you can contract a stationary ammonia genset with full commercial performance guarantees (not a demonstration or joint-development unit)? State the internal commercial-release milestone and its gate criteria. | C12: Separates a product you can buy from a programme you would be funding. | D12: Product release gate plan with dates | E12: Critical | F12: C2
A13: A-08 | B13: Classify the offered configuration: joint development project / pilot, first-of-a-kind commercial unit, or series product. Use your own internal definition and state it. | C13: Determines the whole contracting and de-risking posture. | D13: Written classification statement | E13: Critical | F13: C7
A14: A-09 | B14: Which reference customers may we contact, and can we visit (a) your ammonia testbed and (b) an operating ammonia unit? | C14: Witnessed operation is worth more than any data sheet. | D14: Reference contact list; site visit offer | E14: High | F14: C2
A15: A-10 | B15: Provide your ammonia product roadmap for the next 5 years: unit sizes, TRL steps, dated milestones, and which are funded and committed versus aspirational. | C15: Tells us whether our unit sits before or after the de-risking milestones. | D15: Dated roadmap; funding status per milestone | E15: High | F15: C2
A17: B — Rating, configuration & site conditions
A18: B-01 | B18: State genset electrical output (MWe) at ISO conditions and at our site conditions, and provide the full derate curve versus ambient temperature and relative humidity. | C18: Johor/Singapore ambient is materially above ISO. Good = derate stated, not buried. | D18: Derate curves (power and heat rate) 25-38 degC | E18: Critical | F18: C4
A19: B-02 | B19: Give mechanical output, generator efficiency, package auxiliary load (kWe) and net export at 100 / 75 / 50 / 25 % load on ammonia. | C19: Ammonia packages carry heavy parasitics (fuel skid, N2, after-treatment). Net export is what we sell. | D19: Heat and mass balance at four load points | E19: Critical | F19: C4
A20: B-03 | B20: State the guaranteed net electrical efficiency (% LHV) on ammonia at each load point, with tolerance and the measurement standard applied (e.g. ISO 3046-1, ISO 8528, ASME PTC 17). | C20: A guarantee without a named test standard and tolerance is not a guarantee. | D20: Guarantee schedule with standard and tolerance | E20: Critical | F20: C4
A21: B-04 | B21: State the same engine's efficiency on the fallback fuel(s) (diesel / natural gas) and quantify the ammonia penalty in percentage points. | C21: Sizes the efficiency cost of ammonia firing on identical hardware. | D21: Comparative performance sheet | E21: High | F21: C4
A22: B-05 | B22: Minimum stable load on ammonia (% MCR) and on pilot/back-up fuel; state any time limit for continuous operation at minimum load. | C22: Drives dispatchability and the number of units needed for turndown. | D22: Load range statement with time limits | E22: High | F22: C4
A23: B-06 | B23: Is the maximum ammonia energy share available across the whole load range, or only above a threshold load? Give the achievable ammonia share versus load. | C23: Common constraint: high ammonia share only at high load. Directly reduces annual ammonia substitution. | D23: NH3 share vs. load curve | E23: Critical | F23: C1
A24: B-07 | B24: Confirm number of engines per block, the N+1 philosophy assumed, and the plant impact of a single-unit trip. | C24: Modularity is the engine's main advantage over a turbine; quantify it. | D24: Plant configuration sketch | E24: Medium | F24: C10
A25: B-08 | B25: Give package footprint, weight, engine hall / enclosure requirements, crane heights, and any separation distances driven specifically by ammonia toxicity. | C25: Ammonia toxicity separation can dominate plot area, not the engine itself. | D25: GA drawings; separation distance basis | E25: High | F25: C6
A26: B-09 | B26: State water consumption and cooling options (radiator vs. cooling tower) with heat rejection at site ambient. | C26: Low water use is a claimed engine advantage; confirm it survives the ammonia after-treatment train. | D26: Cooling system datasheet | E26: Medium | F26: C4
A27: B-10 | B27: Give noise and vibration data and foundation requirements. | C27: Standard scope item; needed for the civil interface. | D27: Noise data sheet; foundation loads | E27: Medium | F27: C10
A29: C — Combustion system & combustor maturity
A30: C-01 | B30: Describe the ammonia combustion concept in full: port injection / low-pressure gas admission / high-pressure liquid direct injection / pre-chamber spark / dual-fuel compression ignition. State the injection pressure and the phase of ammonia (liquid or vapour) at the cylinder. | C30: This is the heart of the technology and the primary differentiator between OEMs. | D30: Combustion system description; sectional drawings | E30: Critical | F30: C1
A31: C-02 | B31: State the ignition strategy: pilot liquid fuel (which fuel — MGO, diesel, HVO), pre-chamber, spark, or hydrogen assistance. Is a pilot-free concept offered or on the roadmap, and when? | C31: Pilot fuel is a permanent fossil tail and a permanent second fuel logistics chain. | D31: Ignition system description; pilot fuel spec | E31: Critical | F31: C1
A32: C-03 | B32: State the minimum pilot fuel energy share at 100 / 75 / 50 / 25 % load, how it varies with ambient, and the guaranteed maximum ammonia energy fraction at each load. | C32: Pilot share sets the residual CO2 and the fuel logistics. Published 4-stroke and 2-stroke concepts have quoted pilot shares around 5 % of energy — confirm for this engine. | D32: Pilot share vs. load table; guarantee wording | E32: Critical | F32: C1
A33: C-04 | B33: Ammonia's laminar flame speed is roughly one-fifth that of methane-air. What specific design measures address flame speed, ignition delay and burn duration — combustion chamber geometry, swirl, compression ratio, injection timing, staged injection, hydrogen enrichment, on-board partial cracking? | C33: Tests whether the OEM has engineered for ammonia or merely substituted the fuel. | D33: Design rationale; combustion development report | E33: Critical | F33: C1
A34: C-05 | B34: Is a partial ammonia cracker or hydrogen generation loop part of the package? If yes: cracked fraction, heat source, start-up sequence, and engine behaviour if the cracker trips. | C34: A cracker in the fuel loop adds a whole second technology and a new single point of failure. | D34: Cracker P&ID; trip case analysis | E34: High | F34: C1
A35: C-06 | B35: Provide measured combustion stability data on ammonia: cycle-to-cycle coefficient of variation of IMEP at 100 / 50 / 25 % load, and the observed misfire and partial-burn rate on the testbed. | C35: Numerical proof of combustion robustness. Good = COV of IMEP low and stable across the load range, with a stated misfire rate. | D35: Testbed COV(IMEP) data; misfire statistics | E35: Critical | F35: C1
A36: C-07 | B36: Describe knock and pre-ignition margin on ammonia. Is the pilot fuel the knock-limiting element? How is knock detected and controlled? | C36: Ammonia resists knock; the pilot injection does not. The limit usually migrates to the pilot. | D36: Knock margin study; control description | E36: High | F36: C1
A37: C-08 | B37: Is there per-cylinder combustion sensing (cylinder pressure, ion current, knock sensor) with closed-loop control? State the control authority used to balance cylinders (pilot quantity, ammonia timing, lambda) and the balancing achieved. | C37: Cylinder-to-cylinder imbalance is the classic cause of partial burn and ammonia slip on multi-cylinder engines. | D37: Control system architecture; balancing test data | E37: Critical | F37: C1
A38: C-09 | B38: LOSS OF FIRING: state the detection method, detection time, and automatic response for (a) single-cylinder misfire, (b) multi-cylinder misfire, (c) total flame loss. Does the engine trip, load-shed, or revert automatically to pilot fuel? | C38: The user's core question. Good = fast per-cylinder detection with a defined, tested, automatic response short of a full trip. | D38: Cause-and-effect / trip matrix; test evidence | E38: Critical | F38: C3
A39: C-10 | B39: After a misfire, where does the unburnt ammonia go? State the expected exhaust ammonia spike magnitude and duration, the deflagration risk in the exhaust system and after-treatment, and the mitigations (auto-purge, inerting, forced ventilation, exhaust relief panels). | C39: An unburnt-ammonia excursion is both a toxic release and an explosion hazard in the exhaust train. Frequently under-addressed. | D39: Exhaust excursion study; HAZOP node on misfire | E39: Critical | F39: C3
A40: C-11 | B40: Address lubricating oil compatibility: ammonia and water crossover into the crankcase, oil dilution, nitrate / nitrite / nitric-acid formation and resulting corrosion. State the required lube oil specification and base number, the oil change interval, and the evidence base behind them. | C40: A known and under-published ammonia engine failure path; drives OPEX and bearing life. | D40: Lube oil specification; used-oil analysis from endurance runs | E40: Critical | F40: C1
A41: C-12 | B41: State the materials of the combustion chamber, valves, valve seats, injectors and fuel-wetted parts: ammonia compatibility, exclusion of copper and copper alloys, stress-corrosion-cracking control, and demonstrated component life. | C41: Ammonia attacks copper alloys and can cause SCC in some steels. Material control is a maturity signal. | D41: Material specification list; compatibility assessment | E41: Critical | F41: C1
... A47: C-18 | B47: Which combustion-related failure modes were found during development, and how were they closed out? Provide the relevant FMEA extract. | C47: Willingness to share failure history is itself a maturity and partnership signal. | D47: FMEA extract; corrective action register | E47: High | F47: C1
...

Sheet 2 Assessment Criteria
A1: Sheet 2 — Assessment Criteria, Weights & Scoring Rubric
A2: Ten weighted criteria on a 1-5 scale. Weights below are a PROPOSED starting point reflecting that, for ammonia 4-stroke engines today, demonstrated maturity and de-risking matter more than a point efficiency number — adjust them before scoring. Weights must total 100%. Score anchors are defined at 1, 3 and 5; score 2 and 4 by interpolation.
A4: Ref | B4: Criterion | C4: Weight | D4: What it measures / source questions | E4: Score 1 — unacceptable | F4: Score 3 — acceptable | G4: Score 5 — strong | H4: Evidence required to score
A5: C1 | B5: Ammonia combustion system maturity & robustness | C5: 0.16 | D5: Combustion concept, ignition/pilot strategy, flame-speed engineering, per-cylinder control, combustion stability, materials and lube-oil compatibility, deposits. Questions C-01 to C-18, B-06. | E5: Concept-stage or single-cylinder evidence only; no per-cylinder combustion sensing; no COV(IMEP) or misfire data offered; lube-oil and materials compatibility unaddressed. | F5: Multi-cylinder engine running at the offered ammonia share on a testbed; per-cylinder sensing present; COV(IMEP) and misfire data provided; lube-oil spec defined with some endurance evidence. | G5: Multi-thousand hours on multi-cylinder hardware with teardown evidence; closed-loop per-cylinder combustion control; measured stability across the full load range; type approval held; lube oil, materials and deposits all evidenced from endurance runs. | H5: Testbed reports, COV(IMEP) data, teardown/inspection reports, FMEA extract, type approval certificate, lube-oil analyses.
A6: C2 | B6: Technology readiness & demonstrated evidence | C6: 0.15 | D6: TRL by subsystem, accumulated ammonia hours split by rig/testbed/field, reference fleet, independent verification, marine-to-stationary delta. Questions A-01 to A-10, C-16, C-17, H-07, J-01 to J-06. | E6: No multi-cylinder ammonia hours; no reference unit; no third-party verification; product classified as R&D with no committed commercial release date. | F6: Multi-cylinder ammonia hours accumulated and a first reference unit contracted or under construction; committed release date with defined gates; some independent verification. | G6: Ammonia units in commercial service with published cumulative hours; stationary reference available to visit; independent verification of performance and emissions; TRL stated and justified per subsystem. | H6: Fleet list with hours, reference contacts, third-party verification report, TRL assessment, class/type certificates.
A7: C3 | B7: Fuel transition integrity & loss-of-firing behaviour | C7: 0.11 | D7: Mode map, transition ramp and window, electrical disturbance, measured flame-loss rate, automatic reversion, unburnt-ammonia excursion handling, failure matrix. Questions C-09, C-10, E-01 to E-12, D-11. | E7: Transition behaviour described only qualitatively; no measured flame-loss data; reversion is manual or trips the unit; unburnt-ammonia excursion path not analysed. | F7: Transition sequence defined with a stated load window and ramp rate; automatic reversion to pilot fuel demonstrated on the testbed; purge sequence defined; failure matrix provided. | G7: Grid-connected transition traces showing bumpless, load-holding changeover; measured flame-loss rate from a documented test programme; automatic reversion offered as a contractual guarantee; exhaust excursion HAZOP-closed. | H7: Transition test traces, event logs, cause-and-effect / trip matrix, purge sequence, HAZOP node on misfire.
A8: C4 | B8: Efficiency & performance on ammonia | C8: 0.11 | D8: Guaranteed net efficiency and heat rate at four load points, site-ambient derate, part-load curve, transient and ramp performance, degradation, package parasitics. Questions B-01 to B-05, D-09, F-01 to F-10, E-11. | E8: Catalogue efficiency only, no guarantee, no site-condition correction, no part-load data, parasitic loads undisclosed. | F8: Guaranteed net efficiency at rated load with a named test standard and tolerance; part-load curve and ambient derate provided; parasitics disclosed. | G8: Guaranteed net efficiency at all four load points at site ambient, with correction curves, degradation cap and full parasitic disclosure; part-load flatness and transient response evidenced by test data. | H8: Guarantee schedule with test standard and correction curves, heat and mass balance, derate curves, transient test traces.
A9: C5 | B9: Emissions & GHG integrity (NOx, N2O, ammonia slip) | C9: 0.1 | D9: Measured raw and treated emissions, dedicated N2O catalyst, catalyst temperature window, transient and start-up emissions, regulatory basis, CEMS scope. Questions G-01 to G-10. | E9: Only treated values at rated load offered; no N2O data; no dedicated N2O catalyst; ammonia slip not measured; no regulatory compliance basis named. | F9: Measured raw and treated NOx, N2O and slip at rated load; three-bed after-treatment defined; a named regulatory limit set targeted; slip included in the CEMS scope. | G9: Measured raw and treated values across the full load range including transitions and start-up; dedicated N2O catalyst with life data; emissions guaranteed against a named Singapore or Malaysia limit set already demonstrated in practice. | H9: Measured emissions report with O2 reference, catalyst data sheets, transient emissions data, guarantee schedule, CEMS spec.
A10: C6 | B10: Ammonia fuel supply system & safety design | C10: 0.09 | D10: Fuel train scope and P&ID, fuel quality spec, purge/inerting, vent treatment, double-wall and ppm detection, toxicity-based layout, HAZOP/QRA, SIL. Questions D-01 to D-12, H-01 to H-10, L-05. | E10: Fuel system scope undefined or excluded; no fuel quality spec; venting to atmosphere assumed; no HAZOP or QRA on the package; safety functions not SIL-assessed. | F10: Complete fuel skid P&ID and battery limits; fuel quality spec defined; vent treatment in scope; ppm-level detection philosophy; HAZOP performed. | G10: Fully productised fuel system with closed-out HAZOP/QRA, SIL-verified shutdown functions, defined residual release scenario, certified fuel system, and prior permitting precedent in a comparable jurisdiction. | H10: P&ID, battery limit schedule, fuel spec, HAZID/HAZOP/QRA reports with action register, SIL assessment, certificates.
A11: C7 | B11: Contractual de-risking: guarantees, LDs, LTSA, security | C11: 0.1 | D11: Guarantee list and test basis, LD rates and caps, liability cap, rejection threshold, warranty, LTSA, bonds, FOAK risk sharing, insurability, continuity. Questions A-01, A-08, I-07, J-05, M-01 to M-16. | E11: Guarantees limited to back-up-fuel operation; ammonia share, N2O or ammonia-mode availability excluded; no LDs on performance; no security package; no FOAK risk sharing offered; insurability unaddressed. | F11: Output, efficiency and NOx guaranteed on ammonia with a defined test procedure; delay and performance LDs offered with caps; standard warranty and bonds; LTSA available. | G11: Full guarantee set including ammonia energy share, N2O, ammonia slip and AMMONIA-MODE availability; performance and delay LDs with a rejection threshold; LTSA covering ammonia-specific consumables; parent company guarantee; explicit FOAK risk sharing (staged acceptance / make-good) and evidence of insurer engagement. | H11: Draft guarantee schedule, performance test procedure, LD and liability terms, LTSA term sheet, security package, broker/insurer letter.
A12: C8 | B12: Schedule certainty & long-lead exposure | C12: 0.07 | D12: Long-lead register, critical path, production slot availability and terms, Level 2 schedule, FAT scope including ammonia firing, commissioning prerequisites. Questions I-06, K-01 to K-10. | E12: No lead times offered; no production slot visibility; no Level 2 schedule; FAT scope undefined; commissioning prerequisites not stated. | F12: Long-lead items listed with current lead times; a production slot identified with reservation terms; Level 2 schedule provided; FAT scope defined. | G12: Full long-lead register with sub-suppliers and single-source flags; firm slot with reasonable reservation terms; Level 2 schedule with float analysis; ammonia fired at the works during FAT; commissioning prerequisites and commissioning-fuel supply resolved. | H12: Long-lead register, production slot chart and terms, native Level 2 schedule, FAT procedure, commissioning plan.
A13: C9 | B13: Reliability, availability, maintainability & regional support | C13: 0.06 | D13: Availability and reliability guarantees on ammonia, demonstrated MTBF/MTTR, overhaul intervals and ammonia component-life penalty, spares, condition monitoring, Malaysia/Singapore service network. Questions C-13, C-14, G-05, H-10, I-01 to I-10. | E13: No availability figure for ammonia operation; no maintenance schedule; no regional service presence; ammonia component life unknown. | F13: Availability guarantee offered with exclusions stated; maintenance and overhaul schedule provided; regional service network present; ammonia component-life deltas identified. | G13: Availability guaranteed for ammonia operation and backed by demonstrated MTBF/MTTR; overhaul intervals and ammonia-specific component life quantified against the parent engine; ammonia-trained team based in Malaysia or Singapore; condition monitoring targeted at the ammonia degradation paths. | H13: Availability guarantee wording, RAM data, maintenance and overhaul schedules, spares list with lead times, service network detail.
A14: C10 | B14: Execution model, EPC fit & lifecycle cost transparency | C14: 0.05 | D14: Delivery model and turnkey wrap, preferred/experienced EPC contractors, interface matrix, localisation, price breakdown, ammonia premium, O&M cost basis. Questions B-07, B-10, L-01 to L-09, N-01 to N-06. | E14: Equipment supply only with no interface support; no EPC relationships on ammonia or hydrogen; no price breakdown; ammonia premium not disclosed; O&M basis withheld. | F14: Engineering-plus-equipment offered with a defined interface matrix; EPC contractors named with engine-plant experience; priced scope breakdown provided; indicative O&M basis given. | G14: Turnkey wrap available including the ammonia fuel system; named EPC partners with ammonia or hydrogen fuel-system experience and an approved list for Malaysia; full interface matrix; ammonia premium stated explicitly in $/kW; transparent lifecycle O&M model including catalyst and consumables. | H14: Delivery model options, preferred EPC list with references, interface matrix, priced scope breakdown, O&M cost model.
B15: TOTAL — must equal 100% | C15: =SUM(C5:C14) | D15: =IF(ROUND(C15,6)=1,"Weights OK","ADJUST WEIGHTS — total is not 100%")
A17: KNOCK-OUT GATES — apply BEFORE scoring. A failure here removes the OEM from the comparison; it is not a low score.
A18: Ref | B18: Knock-out gate | C18: Basis | D18: Why it is a knock-out
A19: K1 | B19: No multi-cylinder engine has ever run on ammonia at the offered energy share | C19: Q A-04, A-05, C-16 | D19: Single-cylinder rig data does not de-risk cylinder balancing, turbocharger matching or transient behaviour. Buying against rig data alone is funding development, not procuring equipment.
A20: K2 | B20: OEM will not guarantee any performance parameter on ammonia operation | C20: Q M-01, M-08 | D20: If nothing is guaranteed on ammonia, the entire fuel-substitution case sits with us and cannot be financed or insured.
A21: K3 | B21: No automatic fallback to a back-up fuel on loss of ammonia supply or loss of firing | C21: Q E-06, E-07 | D21: Without automatic reversion, an ammonia-side upset becomes a full plant outage. This is the single most important availability protection for the technology.
A22: K4 | B22: No dedicated N2O control, and untreated N2O not measured | C22: Q G-01, G-03 | D22: N2O has a 100-year GWP around 273x CO2 (see sheet 6). Uncontrolled N2O can erase the greenhouse-gas benefit that justifies the whole ammonia pathway.
A23: K5 | B23: No HAZOP or QRA has been performed on the ammonia package | C23: Q H-03 | D23: Ammonia is regulated on a toxicity basis. Without a closed-out process hazard analysis the package cannot be permitted in Johor or accepted for a Singapore-facing offtake.
A24: K6 | B24: No committed commercial release date for a STATIONARY ammonia genset | C24: Q A-06, A-07, J-04 | D24: A marine-only product with no stationary release plan cannot support a fixed-date stationary project schedule.
A25: K7 | B25: No credible route to insurability for a first-of-a-kind ammonia unit | C25: Q M-13 | D25: Uninsurable equipment cannot reach financial close regardless of its technical merit.
A27: Weights set by: | B27: [name / role] | C27: Date: | D27: [YYYY-MM-DD]
A28: Basis of the proposed weights: | B28: Judgement call, not a sourced figure. Weighted towards maturity (C1+C2 = 31%) and de-risking (C3+C7 = 21%) because no OEM currently sells a proven stationary ammonia 4-stroke genset (see sheet 6); efficiency is weighted lower (C4 = 11%) because the credible efficiency spread between competing ammonia 4-stroke offers is narrow relative to the maturity spread. Adjust to suit the project.

Sheet 3 Scorecard
A1: Sheet 3 — Weighted Scorecard (up to three OEMs)
A2: Criterion names and weights are pulled by formula from sheet 2 — edit them there, not here. Enter only the raw 1-5 scores (yellow) and a one-line justification. Because the weights total 100%, the weighted total lands on the same 1-5 scale.
A4: OEM identity | D4: [OEM A name] | G4: [OEM B name] | J4: [OEM C name]
A5: Ref | B5: Criterion | C5: Weight | D5: Score 1-5 | E5: Weighted | F5: Justification / evidence | G5: Score 1-5 | H5: Weighted | I5: Justification / evidence | J5: Score 1-5 | K5: Weighted | L5: Justification / evidence
A6: ='2 Assessment Criteria'!A5 | B6: ='2 Assessment Criteria'!B5 | C6: ='2 Assessment Criteria'!C5 | E6: =IF(D6="","",D6*$C6) | H6: =IF(G6="","",G6*$C6) | K6: =IF(J6="","",J6*$C6)
A7: ='2 Assessment Criteria'!A6 | B7: ='2 Assessment Criteria'!B6 | C7: ='2 Assessment Criteria'!C6 | E7: =IF(D7="","",D7*$C7) | H7: =IF(G7="","",G7*$C7) | K7: =IF(J7="","",J7*$C7)
A8: ='2 Assessment Criteria'!A7 | B8: ='2 Assessment Criteria'!B7 | C8: ='2 Assessment Criteria'!C7 | E8: =IF(D8="","",D8*$C8) | H8: =IF(G8="","",G8*$C8) | K8: =IF(J8="","",J8*$C8)
A9: ='2 Assessment Criteria'!A8 | B9: ='2 Assessment Criteria'!B8 | C9: ='2 Assessment Criteria'!C8 | E9: =IF(D9="","",D9*$C9) | H9: =IF(G9="","",G9*$C9) | K9: =IF(J9="","",J9*$C9)
A10: ='2 Assessment Criteria'!A9 | B10: ='2 Assessment Criteria'!B9 | C10: ='2 Assessment Criteria'!C9 | E10: =IF(D10="","",D10*$C10) | H10: =IF(G10="","",G10*$C10) | K10: =IF(J10="","",J10*$C10)
A11: ='2 Assessment Criteria'!A10 | B11: ='2 Assessment Criteria'!B10 | C11: ='2 Assessment Criteria'!C10 | E11: =IF(D11="","",D11*$C11) | H11: =IF(G11="","",G11*$C11) | K11: =IF(J11="","",J11*$C11)
A12: ='2 Assessment Criteria'!A11 | B12: ='2 Assessment Criteria'!B11 | C12: ='2 Assessment Criteria'!C11 | E12: =IF(D12="","",D12*$C12) | H12: =IF(G12="","",G12*$C12) | K12: =IF(J12="","",J12*$C12)
A13: ='2 Assessment Criteria'!A12 | B13: ='2 Assessment Criteria'!B12 | C13: ='2 Assessment Criteria'!C12 | E13: =IF(D13="","",D13*$C13) | H13: =IF(G13="","",G13*$C13) | K13: =IF(J13="","",J13*$C13)
A14: ='2 Assessment Criteria'!A13 | B14: ='2 Assessment Criteria'!B13 | C14: ='2 Assessment Criteria'!C13 | E14: =IF(D14="","",D14*$C14) | H14: =IF(G14="","",G14*$C14) | K14: =IF(J14="","",J14*$C14)
A15: ='2 Assessment Criteria'!A14 | B15: ='2 Assessment Criteria'!B14 | C15: ='2 Assessment Criteria'!C14 | E15: =IF(D15="","",D15*$C15) | H15: =IF(G15="","",G15*$C15) | K15: =IF(J15="","",J15*$C15)
B16: WEIGHTED TOTAL (scale 1-5) | C16: =SUM(C6:C15) | E16: =IF(COUNT(D6:D15)=0,"",SUM(E6:E15)) | H16: =IF(COUNT(G6:G15)=0,"",SUM(H6:H15)) | K16: =IF(COUNT(J6:J15)=0,"",SUM(K6:K15))
B17: Equivalent score out of 100 | E17: =IF(E16="","",E16/5) | H17: =IF(H16="","",H16/5) | K17: =IF(K16="","",K16/5)
B18: Criteria scored (of 10) | E18: =COUNT(D6:D15) | H18: =COUNT(G6:G15) | K18: =COUNT(J6:J15)
A20: KNOCK-OUT GATES — complete this block FIRST. Any 'Fail' removes the OEM regardless of its weighted score.
A21: Ref | B21: Knock-out gate | D21: OEM A | F21: Note | G21: OEM B | I21: Note | J21: OEM C | L21: Note
A22: ='2 Assessment Criteria'!A19 | B22: ='2 Assessment Criteria'!B19
A23: ='2 Assessment Criteria'!A20 | B23: ='2 Assessment Criteria'!B20
A24: ='2 Assessment Criteria'!A21 | B24: ='2 Assessment Criteria'!B21
A25: ='2 Assessment Criteria'!A22 | B25: ='2 Assessment Criteria'!B22
A26: ='2 Assessment Criteria'!A23 | B26: ='2 Assessment Criteria'!B23
A27: ='2 Assessment Criteria'!A24 | B27: ='2 Assessment Criteria'!B24
A28: ='2 Assessment Criteria'!A25 | B28: ='2 Assessment Criteria'!B25
B29: KNOCK-OUT VERDICT | D29: =IF(COUNTIF(D22:D28,"Fail")>0,"ELIMINATED",IF(COUNTIF(D22:D28,"Pass")=7,"PROCEED","INCOMPLETE")) | G29: =IF(COUNTIF(G22:G28,"Fail")>0,"ELIMINATED",IF(COUNTIF(G22:G28,"Pass")=7,"PROCEED","INCOMPLETE")) | J29: =IF(COUNTIF(J22:J28,"Fail")>0,"ELIMINATED",IF(COUNTIF(J22:J28,"Pass")=7,"PROCEED","INCOMPLETE"))
A31: SENSITIVITY CHECK
A32: 1. Note the ranking above. Then, on sheet 2, move the largest weight (C1) down 10 percentage points and give those points to C4, and re-read the ranking.
A33: 2. If the ranking flips, the decision is fragile and must be reported as such — do not present a fragile ranking as a conclusion. Restore the weights afterwards.
A34: 3. Treat a gap of less than 0.2 on the 1-5 weighted total as a tie and break it with judgement, not decimals.
A35: 4. Any criterion scored on fewer than three answered Critical questions should be flagged in the justification column as low-confidence.

Sheet 4 Long Lead and Schedule
A1: Sheet 4 — Long-Lead Item Register & Purchase-to-Commissioning Schedule
A2: Populate from questions K-01 to K-10 and I-06. The item list below is a CHECKLIST of what to ask about — no lead times, prices or dates are pre-filled, because none can be stated without the OEM. All yellow cells are for OEM-supplied data.
A4: BLOCK 1 — LONG-LEAD ITEM REGISTER
A5: # | B5: Long-lead item | C5: In whose scope (OEM / EPC / Owner) | D5: Sub-supplier | E5: Single-sourced? (Y/N) | F5: Quoted lead time (weeks from PO) | G5: Date of quote | H5: On critical path? (Y/N) | I5: Risk | J5: Mitigation / action
A6: 1 | B6: Engine block / bedplate and crankshaft
A7: 2 | B7: Cylinder heads, valves and seats (ammonia-compatible materials)
A8: 3 | B8: Ammonia main fuel injectors / gas admission valves
A9: 4 | B9: Pilot fuel injection system
A10: 5 | B10: Turbocharger (ammonia-matched)
A11: 6 | B11: Alternator / generator
A12: 7 | B12: Ammonia fuel conditioning skid (pumps, vaporiser/heater, filtration, buffer)
A13: 8 | B13: Fuel valve train / fuel valve unit (double block and bleed)
A14: 9 | B14: Double-walled ammonia piping, fittings and ventilated annulus
A15: 10 | B15: SCR reactor and NOx catalyst
A16: 11 | B16: Ammonia oxidation / slip catalyst (AMOX / ASC)
A17: 12 | B17: Dedicated N2O catalyst
... A29: 24 | B29: Ammonia-specific capital spares set
B30: Longest quoted lead time (weeks) | F30: =IF(COUNT(F6:F29)=0,"",MAX(F6:F29)) | H30: =COUNTIF(H6:H29,"Y")&" item(s) on critical path"
B31: Single-sourced items | E31: =COUNTIF(E6:E29,"Y")
A33: BLOCK 2 — SCHEDULE FROM PURCHASE ORDER TO COMMERCIAL OPERATION (populate from question K-05)
A34: # | B34: Milestone | C34: Predecessor | D34: OEM duration (weeks) | E34: Cumulative week | F34: Target date | G34: Responsibility | H34: Float (weeks) | I34: Prerequisite from owner | J34: Evidence / status
A35: 1 | B35: Contract effective date / notice to proceed | C35: - | E35: =IF(COUNT($D$35:$D35)=0,"",SUM($D$35:$D35))
A36: 2 | B36: Engineering release / design freeze | C36: 1 | E36: =IF(COUNT($D$35:$D36)=0,"",SUM($D$35:$D36))
A37: 3 | B37: Long-lead purchase orders placed | C37: 2 | E37: =IF(COUNT($D$35:$D37)=0,"",SUM($D$35:$D37))
A38: 4 | B38: Major component manufacture (engine, alternator, turbocharger) | C38: 3 | E38: =IF(COUNT($D$35:$D38)=0,"",SUM($D$35:$D38))
A39: 5 | B39: Ammonia fuel skid and after-treatment manufacture | C39: 3 | E39: =IF(COUNT($D$35:$D39)=0,"",SUM($D$35:$D39))
A40: 6 | B40: Factory acceptance test — mechanical | C40: 4 | E40: =IF(COUNT($D$35:$D40)=0,"",SUM($D$35:$D40))
A41: 7 | B41: Factory acceptance test — ammonia firing at works (confirm if offered) | C41: 6 | E41: =IF(COUNT($D$35:$D41)=0,"",SUM($D$35:$D41))
A42: 8 | B42: Shipment / marine transport to site | C42: 7 | E42: =IF(COUNT($D$35:$D42)=0,"",SUM($D$35:$D42))
A43: 9 | B43: Site delivery and offloading | C43: 8 | E43: =IF(COUNT($D$35:$D43)=0,"",SUM($D$35:$D43))
A44: 10 | B44: Erection and mechanical completion | C44: 9 | E44: =IF(COUNT($D$35:$D44)=0,"",SUM($D$35:$D44))
A45: 11 | B45: Cold commissioning / loop checks / leak testing | C45: 10 | E45: =IF(COUNT($D$35:$D45)=0,"",SUM($D$35:$D45))
A46: 12 | B46: Nitrogen purge and fuel system commissioning | C46: 11 | E46: =IF(COUNT($D$35:$D46)=0,"",SUM($D$35:$D46))
... A54: 20 | B54: Commercial operation date (COD) | C54: 19 | E54: =IF(COUNT($D$35:$D54)=0,"",SUM($D$35:$D54))
B55: TOTAL PO TO COD | D55: =IF(COUNT(D35:D54)=0,"",SUM(D35:D54)) | E55: =IF(D55="","",ROUND(D55/4.345,1)&" months")
A57: • Cumulative week assumes the milestones run strictly in sequence. Where the OEM's Level 2 schedule shows overlap, overwrite the cumulative column with the OEM's own dates and note it.
A58: • Milestone 7 (ammonia fired at the works) is the single largest technical de-risking opportunity in the whole schedule — confirm whether the OEM offers it (question K-07).
A59: • Milestones 15 to 19 are the ammonia-specific acceptance sequence. If the OEM offers staged acceptance (question M-12), COD on back-up fuel can be taken at milestone 14, with ammonia acceptance following separately.
A60: • Commissioning ammonia quantity, source and cost (question K-09) is an owner prerequisite that is routinely missed until it becomes critical path.

Sheet 5 Contract De-risking
A1: Sheet 5 — Contract & Performance De-risking Checklist
A2: Populate from section M (and A-08, I-07, J-05). 'Our target position' is a proposed negotiating start point, not a contractual requirement — agree it internally before the meeting. Yellow columns capture the OEM's actual position.
A4: Ref | B4: Item | C4: What to secure | D4: Our target position (proposed — agree internally) | E4: OEM position | F4: Gap | G4: De-risk action | H4: Owner / by when
A5: GUARANTEE SCOPE
A6: M-01 | B6: Guaranteed parameter list | C6: Every parameter that matters commercially is on the guarantee schedule, not just output. | D6: Guaranteed on ammonia: net output, net efficiency/heat rate, maximum ammonia energy share, NOx, N2O, ammonia slip, availability, reliability, degradation cap, auxiliary load, noise.
A7: M-02 | B7: Test basis and correction curves | C7: A named test standard, stated tolerance, defined test conditions and correction curves for every guaranteed parameter. | D7: ISO 3046-1 / ISO 8528 / ASME PTC 17 as applicable, agreed before contract signature, with correction curves attached as an exhibit.
A8: M-08 | B8: Ammonia-mode availability | C8: An explicit written answer on whether availability is guaranteed for AMMONIA operation or only back-up fuel. | D8: Availability guaranteed for ammonia operation. If refused, the refusal must be explicit and priced into the commercial comparison.
A9: G-08 | B9: Emissions guarantee basis | C9: Emissions guaranteed against a named regulatory limit set the OEM has already demonstrated. | D9: Guaranteed against the applicable Malaysia DOE limit set and, where relevant to the offtake, the Singapore NEA basis; ammonia slip included.
A10: LIQUIDATED DAMAGES & LIABILITY
A11: M-03 | B11: Performance and delay LDs | C11: LD rates and caps as a percentage of contract price, and whether LDs are the sole remedy. | D11: Performance LDs on efficiency, output and ammonia share; delay LDs; caps at market norms; LDs not the sole remedy for a fundamental technology failure.
A12: M-04 | B12: Limitation of liability | C12: The overall liability cap and the treatment of consequential damages. | D12: Liability cap negotiated upward for a first-of-a-kind unit relative to a standard natural-gas supply contract.
A13: M-05 | B13: Rejection threshold | C13: A defined shortfall level at which we may reject, with the remedy stated. | D13: Rejection right at a defined shortfall in ammonia energy share, net efficiency or ammonia-mode availability, with buy-back or replacement.
A14: WARRANTY & LIFECYCLE
A15: M-06 | B15: Warranty | C15: Period, scope, and confirmation that ammonia-specific parts are not carved out. | D15: Extended warranty for the ammonia-specific scope (injectors, fuel skid, catalyst) relative to standard parts, given the absence of field precedent.
A16: M-07 | B16: Long-term service agreement | C16: Structure, term, availability guarantee, and whether ammonia consumables and catalyst are covered. | D16: LTSA covering ammonia-specific consumables, injectors and catalyst replacement, with an availability guarantee and bonus/LD mechanism.
A17: I-07 | B17: Obsolescence commitment | C17: A written parts-availability commitment for the ammonia variant. | D17: Parts availability guaranteed for the design life of the plant, backed by the continuity provisions below.
A18: SECURITY & PAYMENT
A19: M-09 | B19: Security package | C19: Parent company guarantee, advance payment bond, performance bond, warranty bond — issuer, amount, validity. | D19: PCG from the ultimate parent; APB covering 100% of advance payments; performance bond and warranty bond at market norms.
A20: M-10 | B20: Payment milestones | C20: A milestone profile weighted towards demonstrated progress rather than time. | D20: Payment weighted to FAT (especially ammonia firing at works), delivery and ammonia acceptance; slot reservation refundable or creditable.
A21: M-11 | B21: Price validity and escalation | C21: Validity period and a bounded escalation formula. | D21: Fixed price for a defined validity window; any escalation capped and indexed to a published index.
A22: FIRST-OF-A-KIND RISK
A23: A-08 / J-05 | B23: FOAK classification and de-risking | C23: The OEM's own classification of this unit and what additional de-risking it will offer. | D23: Written classification; plus extended factory testing, enhanced guarantees, and step-in / escrow provisions for a FOAK unit.
A24: M-12 | B24: Staged acceptance / risk sharing | C24: Separation of plant commercial operation from ammonia technology proof. | D24: Staged acceptance: COD on back-up fuel, then a separate ammonia acceptance with its own test, LDs and make-good obligation.
A25: M-13 | B25: Insurability | C25: Evidence of insurer engagement for construction all-risk and delay-in-start-up on a FOAK ammonia unit. | D25: Broker or underwriter letter confirming CAR/DSU cover is available, obtained before financial close.
A26: M-14 | B26: IP, escrow and continuity | C26: Protection against product line discontinuation. | D26: Escrow of drawings and control software; licence to a third party on discontinuation; guaranteed spares supply.
A27: LEGAL
A28: M-15 | B28: Force majeure / change in law | C28: Allocation of regulatory change risk for ammonia handling and emissions. | D28: Change in law relating to ammonia handling or emissions treated as a shared or owner risk with a defined adjustment mechanism.
A29: M-16 | B29: Dispute resolution | C29: Governing law, mechanism and seat. | D29: Neutral seat and institutional arbitration; governing law agreed with counsel before term sheet.
A30: L-02 | B30: EPC and execution model | C30: The OEM's preferred/approved EPC contractors and whether it will wrap the ammonia scope. | D30: Named EPC with prior ammonia or hydrogen fuel-system experience and an existing working relationship with the OEM; single-point wrap on the ammonia fuel system preferred.

Sheet 6 Reference Notes
A1: Sheet 6 — Sourced Reference Anchors (to challenge OEM answers in the room)
A2: Carried over from ../memory.md. Every line is tagged Sourced / Derived / Assumption / Not published per repo CLAUDE.md section 7. Use these to test an OEM claim — do NOT present them to the OEM as our requirement, and do not treat any of them as a specification.
A4: Topic | B4: Reference anchor | C4: Status | D4: Source | E4: How to use it in the meeting
A5: Fuel property | B5: Ammonia LHV approximately 18.6 MJ/kg; hydrogen content 17.8 wt%; liquid ammonia approximately 680 kg/m3 (derived as 121 kg H2/m3 divided by 0.178), giving roughly 12.6 GJ/m3. | C5: Sourced / Derived | D5: Textbook constants; Ammonia Energy Association; BBA Consultants (memory.md section 6) | E5: Cross-check the OEM's specific fuel consumption: kg NH3/kWh should reconcile with 18.6 MJ/kg and the quoted efficiency.
A6: Combustion physics | B6: Ammonia laminar flame speed is approximately one fifth that of methane-air. | C6: Sourced | D6: memory.md section 6 (comprehensive comparison) | E6: The root cause of staged combustion, hydrogen enrichment and pilot ignition. Ask what the OEM did about it (question C-04).
A7: Engine efficiency | B7: Reciprocating engine simple-cycle efficiency on ammonia approximately 46-49% LHV, claimed at parity with the dual-fuel LNG twin. Wartsila 34SG on natural gas is 48.9%. | C7: Sourced (OEM claim) | D7: Wartsila; memory.md section 6 | E7: If an OEM quotes materially above this band on ammonia, ask for the measured basis and the load point.
A8: Engine part-load | B8: Engine pulse efficiency above 46% at part load, versus below 36% for an aeroderivative gas turbine. | C8: Sourced (OEM claim) | D8: Wartsila; memory.md section 6 | E8: Flat part-load efficiency is the engine's structural advantage — verify it survives ammonia firing (question F-04).
A9: Product status | B9: No stationary ammonia genset product exists today. Wartsila 25 Ammonia (1.9-3.1 MW; 315 kW/cyl at 900 rpm, 345 kW/cyl at 1000 rpm) is marine, with deliveries from 2028. MAN/Everllence AmmoniaMot 2 four-stroke genset was R&D from August 2024 with a 3.5-year programme. | C9: Sourced | D9: Wartsila; Everllence/MAN ES; memory.md section 6 | E9: The baseline reality check for questions A-06 and A-07. Any claim of a mature stationary product should be tested against this.
A10: Pilot fuel | B10: The MAN B&W ME-LGIA two-stroke uses approximately 5% pilot fuel energy share and achieves above 95% ammonia energy fraction. Shipyard delivery 2026. | C10: Sourced | D10: Everllence/MAN ES; memory.md section 6 | E10: A reference point for question C-03. Note it is two-stroke marine — do not assume the same pilot share on a 4-stroke.
A11: N2O | B11: Nitrous oxide has a 100-year global warming potential of approximately 273 times CO2. | C11: Sourced | D11: IPCC AR6 basis, cited in memory.md section 6 | E11: The reason N2O is a knock-out gate (K4) rather than a scoring line.
A12: N2O — engine | B12: Approximately 20 ppm untreated across loads on ammonia test engines, falling to 2-10 ppm with a catalyst. | C12: Sourced | D12: IHI test engine data via memory.md section 6 | E12: Benchmark for question G-01 and G-03. If the OEM cannot quote an untreated N2O number, that is itself the answer.
A13: Ammonia slip | B13: Assumed 10-30 ppm for a new 4-stroke dual-fuel engine, with a target below 10 ppm. | C13: Assumption (measurement basis IHI/Wartsila) | D13: memory.md section 6 | E13: Labelled an assumption — use it to frame question G-01, not as a specification.
A14: After-treatment | B14: An ammonia engine needs three catalyst beds (SCR, ammonia oxidation / slip catalyst, and a dedicated N2O catalyst), where a gas turbine can use combustor staging plus DeNOx. | C14: Sourced | D14: memory.md section 6 | E14: Directly frames questions G-02, G-03 and G-05 and the catalyst OPEX exposure.
A15: GHG performance | B15: In service on the NYK Sakigake at approximately 95% ammonia with catalyst: 94% GHG reduction, N2O at or below 1% of CO2e. Wartsila 25 Ammonia claims up to 90% GHG reduction at approximately 95% ammonia energy share. | C15: Sourced | D15: NYK; Wartsila; memory.md section 6 | E15: Benchmark the OEM's answer to question G-04 against these published figures.
... A22: Cracked ammonia | B22: Cracked-ammonia combined cycle efficiency rises 47.7% (direct liquid NH3) to 49.1% (vaporised) to 54% (fully cracked H2-N2), conditional on heat integration; a standalone non-integrated cracker lowers net efficiency. | C22: Sourced | D22: memory.md section 6 | E22: Relevant if the OEM proposes an on-board partial cracker (question C-05) — ask where the cracking heat comes from.
A24: Status tags | B24: Sourced = traceable to a named public source. Derived = calculated from sourced inputs, calculation shown in memory.md. Assumption = adopted for analysis and recorded in memory.md section 3, not confirmed. Not published = no public figure exists; must be obtained from the OEM.
A25: Full sources | B25: See ../memory.md section 6 (Sourced Data Registry) and power_generation/NH3_gas_turbine_vs_gas_engine_comprehensive_comparison.md.
